import { ValidatorDomainException } from '../shared/exceptions/validator-domain.exception';
import { User } from './user.entity';

describe('Domain > Entities > User', () => {
  describe('create', () => {
    it('should create a user when passing valid email and password', () => {
      const anEmail = 'john@doe.com';
      const aPassword = '12345678';

      const anUser = User.create({ email: anEmail, password: aPassword });

      expect(anUser).toBeInstanceOf(User);
      expect(anUser.getEmail()).toBe(anEmail);
      expect(anUser.getPassword()).not.toBe(aPassword);
      expect(anUser.comparePassword(aPassword)).toBe(true);
      expect(anUser.getId()).toBeDefined();
      expect(anUser.getId().length).toBe(36);
      expect(anUser.getCreatedAt()).toBeInstanceOf(Date);
      expect(anUser.getUpdatedAt()).toBeInstanceOf(Date);
    });

    it('should throw an error when passing invalid email', () => {
      const anInvalidEmail = 'invalid-email';
      const aPassword = '12345678';

      const anError = () => {
        User.create({ email: anInvalidEmail, password: aPassword });
      };

      expect(anError).toThrow(ValidatorDomainException);
    });

    it('should throw an error when passing invalid password', () => {
      const anEmail = 'john@doe.com';
      const anInvalidPassword = '1234';

      const anError = () => {
        User.create({ email: anEmail, password: anInvalidPassword });
      };

      expect(anError).toThrow(ValidatorDomainException);
    });
  });
});
